### `ERR_UNAVAILABLE_DURING_EXIT`

Function was called within a [`process.on('exit')`][] handler that shouldn't be
called within [`process.on('exit')`][] handler.

<a id="ERR_UNCAUGHT_EXCEPTION_CAPTURE_ALREADY_SET"></a>
